Traceback (most recent call last):
  File "/env/export/bigtmp2/cassiope/Cassiope-MAG-Clustering/main_to_lp.py", line 630, in <module>
    __main__()
    ~~~~~~~~^^
  File "/env/export/bigtmp2/cassiope/Cassiope-MAG-Clustering/main_to_lp.py", line 620, in __main__
    ctl.ground([("base", [])])
    ~~~~~~~~~~^^^^^^^^^^^^^^^^
  File "/env/cns/home/pgiraude/.conda/envs/clingo/lib/python3.13/site-packages/clingo/control.py", line 565, in ground
    _handle_error(
    ~~~~~~~~~~~~~^
        _lib.clingo_control_ground(self._rep, c_parts, len(parts), c_cb, c_data),
        ^^^^^^^^^^^^^^^^^^^^^^^^^^^^^^^^^^^^^^^^^^^^^^^^^^^^^^^^^^^^^^^^^^^^^^^^^
        data,
        ^^^^^
    )
    ^
  File "/env/cns/home/pgiraude/.conda/envs/clingo/lib/python3.13/site-packages/clingo/_internal.py", line 81, in _handle_error
    raise RuntimeError(msg)
RuntimeError: Clasp::Asp::PrgNode::PrgNode(Clasp::uint32, bool)@403: Value too large for defined data type: Id out of range
